<?xml version="1.0" encoding="UTF-8"?>
<!-- Generated by org.testng.reporters.JUnitReportReporter -->
<testsuite hostname="DESKTOP-EA5FGKH" name="dataproviderDemo.DDTExcelReader" tests="7" failures="1" timestamp="23 Oct 2019 18:20:08 GMT" time="210.144" errors="0">
  <testcase name="TestLogin" time="26.185" classname="dataproviderDemo.DDTExcelReader">
    <failure type="java.lang.AssertionError" message="User Not able to Login - Invalid Credentails expected [true] but found [false]">
      <![CDATA[java.lang.AssertionError: User Not able to Login - Invalid Credentails expected [true] but found [false]
	at org.testng.Assert.fail(Assert.java:94)
	at org.testng.Assert.failNotEquals(Assert.java:513)
	at org.testng.Assert.assertTrue(Assert.java:42)
	at dataproviderDemo.DDTExcelReader.TestLogin(DDTExcelReader.java:33)
	at sun.reflect.NativeMethodAccessorImpl.invoke0(Native Method)
	at sun.reflect.NativeMethodAccessorImpl.invoke(Unknown Source)
	at sun.reflect.DelegatingMethodAccessorImpl.invoke(Unknown Source)
	at java.lang.reflect.Method.invoke(Unknown Source)
	at org.testng.internal.MethodInvocationHelper.invokeMethod(MethodInvocationHelper.java:86)
	at org.testng.internal.Invoker.invokeMethod(Invoker.java:646)
	at org.testng.internal.Invoker.invokeTestMethod(Invoker.java:823)
	at org.testng.internal.Invoker.invokeTestMethods(Invoker.java:1131)
	at org.testng.internal.TestMethodWorker.invokeTestMethods(TestMethodWorker.java:129)
	at org.testng.internal.TestMethodWorker.run(TestMethodWorker.java:112)
	at org.testng.TestRunner.privateRun(TestRunner.java:778)
	at org.testng.TestRunner.run(TestRunner.java:632)
	at org.testng.SuiteRunner.runTest(SuiteRunner.java:366)
	at org.testng.SuiteRunner.runSequentially(SuiteRunner.java:361)
	at org.testng.SuiteRunner.privateRun(SuiteRunner.java:319)
	at org.testng.SuiteRunner.run(SuiteRunner.java:268)
	at org.testng.SuiteRunnerWorker.runSuite(SuiteRunnerWorker.java:52)
	at org.testng.SuiteRunnerWorker.run(SuiteRunnerWorker.java:86)
	at org.testng.TestNG.runSuitesSequentially(TestNG.java:1225)
	at org.testng.TestNG.runSuitesLocally(TestNG.java:1150)
	at org.testng.TestNG.runSuites(TestNG.java:1075)
	at org.testng.TestNG.run(TestNG.java:1047)
	at org.testng.remote.AbstractRemoteTestNG.run(AbstractRemoteTestNG.java:126)
	at org.testng.remote.RemoteTestNG.initAndRun(RemoteTestNG.java:137)
	at org.testng.remote.RemoteTestNG.main(RemoteTestNG.java:58)
]]>
    </failure>
  </testcase> <!-- TestLogin -->
  <testcase name="TestLogin" time="30.737" classname="dataproviderDemo.DDTExcelReader"/>
  <testcase name="TestLogin" time="31.247" classname="dataproviderDemo.DDTExcelReader"/>
  <testcase name="TestLogin" time="30.451" classname="dataproviderDemo.DDTExcelReader"/>
  <testcase name="TestLogin" time="30.193" classname="dataproviderDemo.DDTExcelReader"/>
  <testcase name="TestLogin" time="30.176" classname="dataproviderDemo.DDTExcelReader"/>
  <testcase name="TestLogin" time="31.155" classname="dataproviderDemo.DDTExcelReader"/>
</testsuite> <!-- dataproviderDemo.DDTExcelReader -->
